Exception in thread Thread-1:
Traceback (most recent call last):
  File "/usr/lib/python3.10/threading.py", line 1016, in _bootstrap_inner
    self.run()
  File "/home/office_user/programming_bench/env/lib/python3.10/site-packages/redis/client.py", line 3718, in run
    pubsub.get_message(ignore_subscribe_messages=True,
  File "/home/office_user/programming_bench/env/lib/python3.10/site-packages/redis/client.py", line 3617, in get_message
    response = self.parse_response(block=False, timeout=timeout)
  File "/home/office_user/programming_bench/env/lib/python3.10/site-packages/redis/client.py", line 3503, in parse_response
    if not block and not conn.can_read(timeout=timeout):
  File "/home/office_user/programming_bench/env/lib/python3.10/site-packages/redis/connection.py", line 734, in can_read
    return self._parser.can_read(timeout)
  File "/home/office_user/programming_bench/env/lib/python3.10/site-packages/redis/connection.py", line 416, in can_read
    return self.read_from_socket(timeout=timeout,
  File "/home/office_user/programming_bench/env/lib/python3.10/site-packages/redis/connection.py", line 429, in read_from_socket
    raise ConnectionError(SERVER_CLOSED_CONNECTION_ERROR)
redis.exceptions.ConnectionError: Connection closed by server.
Exception in thread Thread-1:
Traceback (most recent call last):
  File "/usr/lib/python3.10/threading.py", line 1016, in _bootstrap_inner
    self.run()
  File "/home/office_user/programming_bench/env/lib/python3.10/site-packages/redis/client.py", line 3718, in run
    pubsub.get_message(ignore_subscribe_messages=True,
  File "/home/office_user/programming_bench/env/lib/python3.10/site-packages/redis/client.py", line 3617, in get_message
    response = self.parse_response(block=False, timeout=timeout)
  File "/home/office_user/programming_bench/env/lib/python3.10/site-packages/redis/client.py", line 3503, in parse_response
    if not block and not conn.can_read(timeout=timeout):
  File "/home/office_user/programming_bench/env/lib/python3.10/site-packages/redis/connection.py", line 734, in can_read
    return self._parser.can_read(timeout)
  File "/home/office_user/programming_bench/env/lib/python3.10/site-packages/redis/connection.py", line 416, in can_read
    return self.read_from_socket(timeout=timeout,
  File "/home/office_user/programming_bench/env/lib/python3.10/site-packages/redis/connection.py", line 429, in read_from_socket
    raise ConnectionError(SERVER_CLOSED_CONNECTION_ERROR)
redis.exceptions.ConnectionError: Connection closed by server.
Exception in thread Thread-1:
Traceback (most recent call last):
  File "/usr/lib/python3.10/threading.py", line 1016, in _bootstrap_inner
    self.run()
  File "/home/office_user/programming_bench/env/lib/python3.10/site-packages/redis/client.py", line 3718, in run
    pubsub.get_message(ignore_subscribe_messages=True,
  File "/home/office_user/programming_bench/env/lib/python3.10/site-packages/redis/client.py", line 3617, in get_message
    response = self.parse_response(block=False, timeout=timeout)
  File "/home/office_user/programming_bench/env/lib/python3.10/site-packages/redis/client.py", line 3503, in parse_response
    if not block and not conn.can_read(timeout=timeout):
  File "/home/office_user/programming_bench/env/lib/python3.10/site-packages/redis/connection.py", line 734, in can_read
    return self._parser.can_read(timeout)
  File "/home/office_user/programming_bench/env/lib/python3.10/site-packages/redis/connection.py", line 416, in can_read
    return self.read_from_socket(timeout=timeout,
  File "/home/office_user/programming_bench/env/lib/python3.10/site-packages/redis/connection.py", line 429, in read_from_socket
    raise ConnectionError(SERVER_CLOSED_CONNECTION_ERROR)
redis.exceptions.ConnectionError: Connection closed by server.
/home/office_user/programming_bench/env/lib/python3.10/site-packages/botocore/httpsession.py:19: DeprecationWarning: 'urllib3.contrib.pyopenssl' module is deprecated and will be removed in a future release of urllib3 2.x. Read more in this issue: https://github.com/urllib3/urllib3/issues/2680
  from urllib3.contrib.pyopenssl import orig_util_SSLContext as SSLContext
/home/office_user/programming_bench/env/lib/python3.10/site-packages/botocore/httpsession.py:19: DeprecationWarning: 'urllib3.contrib.pyopenssl' module is deprecated and will be removed in a future release of urllib3 2.x. Read more in this issue: https://github.com/urllib3/urllib3/issues/2680
  from urllib3.contrib.pyopenssl import orig_util_SSLContext as SSLContext
/home/office_user/programming_bench/env/lib/python3.10/site-packages/botocore/httpsession.py:19: DeprecationWarning: 'urllib3.contrib.pyopenssl' module is deprecated and will be removed in a future release of urllib3 2.x. Read more in this issue: https://github.com/urllib3/urllib3/issues/2680
  from urllib3.contrib.pyopenssl import orig_util_SSLContext as SSLContext
fatal: No remote configured to list refs from.
Traceback (most recent call last):
  File "/home/office_user/programming_bench/env/lib/python3.10/site-packages/redis/connection.py", line 559, in connect
    sock = self._connect()
  File "/home/office_user/programming_bench/env/lib/python3.10/site-packages/redis/connection.py", line 615, in _connect
    raise err
  File "/home/office_user/programming_bench/env/lib/python3.10/site-packages/redis/connection.py", line 603, in _connect
    sock.connect(socket_address)
ConnectionRefusedError: [Errno 111] Connection refused

During handling of the above exception, another exception occurred:

Traceback (most recent call last):
  File "/home/office_user/programming_bench/apps/frappe/frappe/monitor.py", line 118, in flush
    logs = frappe.cache().lrange(MONITOR_REDIS_KEY, 0, -1)
  File "/home/office_user/programming_bench/apps/frappe/frappe/utils/redis_wrapper.py", line 146, in lrange
    return super().lrange(self.make_key(key), start, stop)
  File "/home/office_user/programming_bench/env/lib/python3.10/site-packages/redis/client.py", line 1975, in lrange
    return self.execute_command('LRANGE', name, start, end)
  File "/home/office_user/programming_bench/env/lib/python3.10/site-packages/redis/client.py", line 898, in execute_command
    conn = self.connection or pool.get_connection(command_name, **options)
  File "/home/office_user/programming_bench/env/lib/python3.10/site-packages/redis/connection.py", line 1192, in get_connection
    connection.connect()
  File "/home/office_user/programming_bench/env/lib/python3.10/site-packages/redis/connection.py", line 563, in connect
    raise ConnectionError(self._error_message(e))
redis.exceptions.ConnectionError: Error 111 connecting to localhost:13001. Connection refused.
Traceback (most recent call last):
  File "/home/office_user/programming_bench/env/lib/python3.10/site-packages/redis/connection.py", line 559, in connect
    sock = self._connect()
  File "/home/office_user/programming_bench/env/lib/python3.10/site-packages/redis/connection.py", line 615, in _connect
    raise err
  File "/home/office_user/programming_bench/env/lib/python3.10/site-packages/redis/connection.py", line 603, in _connect
    sock.connect(socket_address)
ConnectionRefusedError: [Errno 111] Connection refused

During handling of the above exception, another exception occurred:

Traceback (most recent call last):
  File "/home/office_user/programming_bench/apps/frappe/frappe/monitor.py", line 118, in flush
    logs = frappe.cache().lrange(MONITOR_REDIS_KEY, 0, -1)
  File "/home/office_user/programming_bench/apps/frappe/frappe/utils/redis_wrapper.py", line 146, in lrange
    return super().lrange(self.make_key(key), start, stop)
  File "/home/office_user/programming_bench/env/lib/python3.10/site-packages/redis/client.py", line 1975, in lrange
    return self.execute_command('LRANGE', name, start, end)
  File "/home/office_user/programming_bench/env/lib/python3.10/site-packages/redis/client.py", line 898, in execute_command
    conn = self.connection or pool.get_connection(command_name, **options)
  File "/home/office_user/programming_bench/env/lib/python3.10/site-packages/redis/connection.py", line 1192, in get_connection
    connection.connect()
  File "/home/office_user/programming_bench/env/lib/python3.10/site-packages/redis/connection.py", line 563, in connect
    raise ConnectionError(self._error_message(e))
redis.exceptions.ConnectionError: Error 111 connecting to localhost:13001. Connection refused.
Traceback (most recent call last):
  File "/home/office_user/programming_bench/env/lib/python3.10/site-packages/redis/connection.py", line 559, in connect
    sock = self._connect()
  File "/home/office_user/programming_bench/env/lib/python3.10/site-packages/redis/connection.py", line 615, in _connect
    raise err
  File "/home/office_user/programming_bench/env/lib/python3.10/site-packages/redis/connection.py", line 603, in _connect
    sock.connect(socket_address)
ConnectionRefusedError: [Errno 111] Connection refused

During handling of the above exception, another exception occurred:

Traceback (most recent call last):
  File "/home/office_user/programming_bench/apps/frappe/frappe/monitor.py", line 118, in flush
    logs = frappe.cache().lrange(MONITOR_REDIS_KEY, 0, -1)
  File "/home/office_user/programming_bench/apps/frappe/frappe/utils/redis_wrapper.py", line 146, in lrange
    return super().lrange(self.make_key(key), start, stop)
  File "/home/office_user/programming_bench/env/lib/python3.10/site-packages/redis/client.py", line 1975, in lrange
    return self.execute_command('LRANGE', name, start, end)
  File "/home/office_user/programming_bench/env/lib/python3.10/site-packages/redis/client.py", line 898, in execute_command
    conn = self.connection or pool.get_connection(command_name, **options)
  File "/home/office_user/programming_bench/env/lib/python3.10/site-packages/redis/connection.py", line 1192, in get_connection
    connection.connect()
  File "/home/office_user/programming_bench/env/lib/python3.10/site-packages/redis/connection.py", line 563, in connect
    raise ConnectionError(self._error_message(e))
redis.exceptions.ConnectionError: Error 111 connecting to localhost:13001. Connection refused.
Traceback (most recent call last):
  File "/home/office_user/programming_bench/env/lib/python3.10/site-packages/redis/connection.py", line 559, in connect
    sock = self._connect()
  File "/home/office_user/programming_bench/env/lib/python3.10/site-packages/redis/connection.py", line 615, in _connect
    raise err
  File "/home/office_user/programming_bench/env/lib/python3.10/site-packages/redis/connection.py", line 603, in _connect
    sock.connect(socket_address)
ConnectionRefusedError: [Errno 111] Connection refused

During handling of the above exception, another exception occurred:

Traceback (most recent call last):
  File "/home/office_user/programming_bench/apps/frappe/frappe/monitor.py", line 118, in flush
    logs = frappe.cache().lrange(MONITOR_REDIS_KEY, 0, -1)
  File "/home/office_user/programming_bench/apps/frappe/frappe/utils/redis_wrapper.py", line 146, in lrange
    return super().lrange(self.make_key(key), start, stop)
  File "/home/office_user/programming_bench/env/lib/python3.10/site-packages/redis/client.py", line 1975, in lrange
    return self.execute_command('LRANGE', name, start, end)
  File "/home/office_user/programming_bench/env/lib/python3.10/site-packages/redis/client.py", line 898, in execute_command
    conn = self.connection or pool.get_connection(command_name, **options)
  File "/home/office_user/programming_bench/env/lib/python3.10/site-packages/redis/connection.py", line 1192, in get_connection
    connection.connect()
  File "/home/office_user/programming_bench/env/lib/python3.10/site-packages/redis/connection.py", line 563, in connect
    raise ConnectionError(self._error_message(e))
redis.exceptions.ConnectionError: Error 111 connecting to localhost:13001. Connection refused.
Traceback (most recent call last):
  File "/home/office_user/programming_bench/env/lib/python3.10/site-packages/redis/connection.py", line 559, in connect
    sock = self._connect()
  File "/home/office_user/programming_bench/env/lib/python3.10/site-packages/redis/connection.py", line 615, in _connect
    raise err
  File "/home/office_user/programming_bench/env/lib/python3.10/site-packages/redis/connection.py", line 603, in _connect
    sock.connect(socket_address)
ConnectionRefusedError: [Errno 111] Connection refused

During handling of the above exception, another exception occurred:

Traceback (most recent call last):
  File "/home/office_user/programming_bench/apps/frappe/frappe/monitor.py", line 118, in flush
    logs = frappe.cache().lrange(MONITOR_REDIS_KEY, 0, -1)
  File "/home/office_user/programming_bench/apps/frappe/frappe/utils/redis_wrapper.py", line 146, in lrange
    return super().lrange(self.make_key(key), start, stop)
  File "/home/office_user/programming_bench/env/lib/python3.10/site-packages/redis/client.py", line 1975, in lrange
    return self.execute_command('LRANGE', name, start, end)
  File "/home/office_user/programming_bench/env/lib/python3.10/site-packages/redis/client.py", line 898, in execute_command
    conn = self.connection or pool.get_connection(command_name, **options)
  File "/home/office_user/programming_bench/env/lib/python3.10/site-packages/redis/connection.py", line 1192, in get_connection
    connection.connect()
  File "/home/office_user/programming_bench/env/lib/python3.10/site-packages/redis/connection.py", line 563, in connect
    raise ConnectionError(self._error_message(e))
redis.exceptions.ConnectionError: Error 111 connecting to localhost:13001. Connection refused.
Traceback (most recent call last):
  File "/home/office_user/programming_bench/env/lib/python3.10/site-packages/redis/connection.py", line 559, in connect
    sock = self._connect()
  File "/home/office_user/programming_bench/env/lib/python3.10/site-packages/redis/connection.py", line 615, in _connect
    raise err
  File "/home/office_user/programming_bench/env/lib/python3.10/site-packages/redis/connection.py", line 603, in _connect
    sock.connect(socket_address)
ConnectionRefusedError: [Errno 111] Connection refused

During handling of the above exception, another exception occurred:

Traceback (most recent call last):
  File "/home/office_user/programming_bench/apps/frappe/frappe/monitor.py", line 118, in flush
    logs = frappe.cache().lrange(MONITOR_REDIS_KEY, 0, -1)
  File "/home/office_user/programming_bench/apps/frappe/frappe/utils/redis_wrapper.py", line 146, in lrange
    return super().lrange(self.make_key(key), start, stop)
  File "/home/office_user/programming_bench/env/lib/python3.10/site-packages/redis/client.py", line 1975, in lrange
    return self.execute_command('LRANGE', name, start, end)
  File "/home/office_user/programming_bench/env/lib/python3.10/site-packages/redis/client.py", line 898, in execute_command
    conn = self.connection or pool.get_connection(command_name, **options)
  File "/home/office_user/programming_bench/env/lib/python3.10/site-packages/redis/connection.py", line 1192, in get_connection
    connection.connect()
  File "/home/office_user/programming_bench/env/lib/python3.10/site-packages/redis/connection.py", line 563, in connect
    raise ConnectionError(self._error_message(e))
redis.exceptions.ConnectionError: Error 111 connecting to localhost:13001. Connection refused.
Traceback (most recent call last):
  File "/home/office_user/programming_bench/env/lib/python3.10/site-packages/redis/connection.py", line 559, in connect
    sock = self._connect()
  File "/home/office_user/programming_bench/env/lib/python3.10/site-packages/redis/connection.py", line 615, in _connect
    raise err
  File "/home/office_user/programming_bench/env/lib/python3.10/site-packages/redis/connection.py", line 603, in _connect
    sock.connect(socket_address)
ConnectionRefusedError: [Errno 111] Connection refused

During handling of the above exception, another exception occurred:

Traceback (most recent call last):
  File "/home/office_user/programming_bench/apps/frappe/frappe/monitor.py", line 118, in flush
    logs = frappe.cache().lrange(MONITOR_REDIS_KEY, 0, -1)
  File "/home/office_user/programming_bench/apps/frappe/frappe/utils/redis_wrapper.py", line 146, in lrange
    return super().lrange(self.make_key(key), start, stop)
  File "/home/office_user/programming_bench/env/lib/python3.10/site-packages/redis/client.py", line 1975, in lrange
    return self.execute_command('LRANGE', name, start, end)
  File "/home/office_user/programming_bench/env/lib/python3.10/site-packages/redis/client.py", line 898, in execute_command
    conn = self.connection or pool.get_connection(command_name, **options)
  File "/home/office_user/programming_bench/env/lib/python3.10/site-packages/redis/connection.py", line 1192, in get_connection
    connection.connect()
  File "/home/office_user/programming_bench/env/lib/python3.10/site-packages/redis/connection.py", line 563, in connect
    raise ConnectionError(self._error_message(e))
redis.exceptions.ConnectionError: Error 111 connecting to localhost:13001. Connection refused.
Traceback (most recent call last):
  File "/home/office_user/programming_bench/env/lib/python3.10/site-packages/redis/connection.py", line 559, in connect
    sock = self._connect()
  File "/home/office_user/programming_bench/env/lib/python3.10/site-packages/redis/connection.py", line 615, in _connect
    raise err
  File "/home/office_user/programming_bench/env/lib/python3.10/site-packages/redis/connection.py", line 603, in _connect
    sock.connect(socket_address)
ConnectionRefusedError: [Errno 111] Connection refused

During handling of the above exception, another exception occurred:

Traceback (most recent call last):
  File "/home/office_user/programming_bench/apps/frappe/frappe/monitor.py", line 118, in flush
    logs = frappe.cache().lrange(MONITOR_REDIS_KEY, 0, -1)
  File "/home/office_user/programming_bench/apps/frappe/frappe/utils/redis_wrapper.py", line 146, in lrange
    return super().lrange(self.make_key(key), start, stop)
  File "/home/office_user/programming_bench/env/lib/python3.10/site-packages/redis/client.py", line 1975, in lrange
    return self.execute_command('LRANGE', name, start, end)
  File "/home/office_user/programming_bench/env/lib/python3.10/site-packages/redis/client.py", line 898, in execute_command
    conn = self.connection or pool.get_connection(command_name, **options)
  File "/home/office_user/programming_bench/env/lib/python3.10/site-packages/redis/connection.py", line 1192, in get_connection
    connection.connect()
  File "/home/office_user/programming_bench/env/lib/python3.10/site-packages/redis/connection.py", line 563, in connect
    raise ConnectionError(self._error_message(e))
redis.exceptions.ConnectionError: Error 111 connecting to localhost:13001. Connection refused.
Traceback (most recent call last):
  File "/home/office_user/programming_bench/env/lib/python3.10/site-packages/redis/connection.py", line 559, in connect
    sock = self._connect()
  File "/home/office_user/programming_bench/env/lib/python3.10/site-packages/redis/connection.py", line 615, in _connect
    raise err
  File "/home/office_user/programming_bench/env/lib/python3.10/site-packages/redis/connection.py", line 603, in _connect
    sock.connect(socket_address)
ConnectionRefusedError: [Errno 111] Connection refused

During handling of the above exception, another exception occurred:

Traceback (most recent call last):
  File "/home/office_user/programming_bench/apps/frappe/frappe/monitor.py", line 118, in flush
    logs = frappe.cache().lrange(MONITOR_REDIS_KEY, 0, -1)
  File "/home/office_user/programming_bench/apps/frappe/frappe/utils/redis_wrapper.py", line 146, in lrange
    return super().lrange(self.make_key(key), start, stop)
  File "/home/office_user/programming_bench/env/lib/python3.10/site-packages/redis/client.py", line 1975, in lrange
    return self.execute_command('LRANGE', name, start, end)
  File "/home/office_user/programming_bench/env/lib/python3.10/site-packages/redis/client.py", line 898, in execute_command
    conn = self.connection or pool.get_connection(command_name, **options)
  File "/home/office_user/programming_bench/env/lib/python3.10/site-packages/redis/connection.py", line 1192, in get_connection
    connection.connect()
  File "/home/office_user/programming_bench/env/lib/python3.10/site-packages/redis/connection.py", line 563, in connect
    raise ConnectionError(self._error_message(e))
redis.exceptions.ConnectionError: Error 111 connecting to localhost:13001. Connection refused.
Traceback (most recent call last):
  File "/home/office_user/programming_bench/env/lib/python3.10/site-packages/redis/connection.py", line 559, in connect
    sock = self._connect()
  File "/home/office_user/programming_bench/env/lib/python3.10/site-packages/redis/connection.py", line 615, in _connect
    raise err
  File "/home/office_user/programming_bench/env/lib/python3.10/site-packages/redis/connection.py", line 603, in _connect
    sock.connect(socket_address)
ConnectionRefusedError: [Errno 111] Connection refused

During handling of the above exception, another exception occurred:

Traceback (most recent call last):
  File "/home/office_user/programming_bench/apps/frappe/frappe/monitor.py", line 118, in flush
    logs = frappe.cache().lrange(MONITOR_REDIS_KEY, 0, -1)
  File "/home/office_user/programming_bench/apps/frappe/frappe/utils/redis_wrapper.py", line 146, in lrange
    return super().lrange(self.make_key(key), start, stop)
  File "/home/office_user/programming_bench/env/lib/python3.10/site-packages/redis/client.py", line 1975, in lrange
    return self.execute_command('LRANGE', name, start, end)
  File "/home/office_user/programming_bench/env/lib/python3.10/site-packages/redis/client.py", line 898, in execute_command
    conn = self.connection or pool.get_connection(command_name, **options)
  File "/home/office_user/programming_bench/env/lib/python3.10/site-packages/redis/connection.py", line 1192, in get_connection
    connection.connect()
  File "/home/office_user/programming_bench/env/lib/python3.10/site-packages/redis/connection.py", line 563, in connect
    raise ConnectionError(self._error_message(e))
redis.exceptions.ConnectionError: Error 111 connecting to localhost:13001. Connection refused.
Traceback (most recent call last):
  File "/home/office_user/programming_bench/env/lib/python3.10/site-packages/redis/connection.py", line 559, in connect
    sock = self._connect()
  File "/home/office_user/programming_bench/env/lib/python3.10/site-packages/redis/connection.py", line 615, in _connect
    raise err
  File "/home/office_user/programming_bench/env/lib/python3.10/site-packages/redis/connection.py", line 603, in _connect
    sock.connect(socket_address)
ConnectionRefusedError: [Errno 111] Connection refused

During handling of the above exception, another exception occurred:

Traceback (most recent call last):
  File "/home/office_user/programming_bench/apps/frappe/frappe/monitor.py", line 118, in flush
    logs = frappe.cache().lrange(MONITOR_REDIS_KEY, 0, -1)
  File "/home/office_user/programming_bench/apps/frappe/frappe/utils/redis_wrapper.py", line 146, in lrange
    return super().lrange(self.make_key(key), start, stop)
  File "/home/office_user/programming_bench/env/lib/python3.10/site-packages/redis/client.py", line 1975, in lrange
    return self.execute_command('LRANGE', name, start, end)
  File "/home/office_user/programming_bench/env/lib/python3.10/site-packages/redis/client.py", line 898, in execute_command
    conn = self.connection or pool.get_connection(command_name, **options)
  File "/home/office_user/programming_bench/env/lib/python3.10/site-packages/redis/connection.py", line 1192, in get_connection
    connection.connect()
  File "/home/office_user/programming_bench/env/lib/python3.10/site-packages/redis/connection.py", line 563, in connect
    raise ConnectionError(self._error_message(e))
redis.exceptions.ConnectionError: Error 111 connecting to localhost:13001. Connection refused.
Traceback (most recent call last):
  File "/home/office_user/programming_bench/env/lib/python3.10/site-packages/redis/connection.py", line 559, in connect
    sock = self._connect()
  File "/home/office_user/programming_bench/env/lib/python3.10/site-packages/redis/connection.py", line 615, in _connect
    raise err
  File "/home/office_user/programming_bench/env/lib/python3.10/site-packages/redis/connection.py", line 603, in _connect
    sock.connect(socket_address)
ConnectionRefusedError: [Errno 111] Connection refused

During handling of the above exception, another exception occurred:

Traceback (most recent call last):
  File "/home/office_user/programming_bench/apps/frappe/frappe/monitor.py", line 118, in flush
    logs = frappe.cache().lrange(MONITOR_REDIS_KEY, 0, -1)
  File "/home/office_user/programming_bench/apps/frappe/frappe/utils/redis_wrapper.py", line 146, in lrange
    return super().lrange(self.make_key(key), start, stop)
  File "/home/office_user/programming_bench/env/lib/python3.10/site-packages/redis/client.py", line 1975, in lrange
    return self.execute_command('LRANGE', name, start, end)
  File "/home/office_user/programming_bench/env/lib/python3.10/site-packages/redis/client.py", line 898, in execute_command
    conn = self.connection or pool.get_connection(command_name, **options)
  File "/home/office_user/programming_bench/env/lib/python3.10/site-packages/redis/connection.py", line 1192, in get_connection
    connection.connect()
  File "/home/office_user/programming_bench/env/lib/python3.10/site-packages/redis/connection.py", line 563, in connect
    raise ConnectionError(self._error_message(e))
redis.exceptions.ConnectionError: Error 111 connecting to localhost:13001. Connection refused.
Traceback (most recent call last):
  File "/home/office_user/programming_bench/env/lib/python3.10/site-packages/redis/connection.py", line 559, in connect
    sock = self._connect()
  File "/home/office_user/programming_bench/env/lib/python3.10/site-packages/redis/connection.py", line 615, in _connect
    raise err
  File "/home/office_user/programming_bench/env/lib/python3.10/site-packages/redis/connection.py", line 603, in _connect
    sock.connect(socket_address)
ConnectionRefusedError: [Errno 111] Connection refused

During handling of the above exception, another exception occurred:

Traceback (most recent call last):
  File "/home/office_user/programming_bench/apps/frappe/frappe/monitor.py", line 118, in flush
    logs = frappe.cache().lrange(MONITOR_REDIS_KEY, 0, -1)
  File "/home/office_user/programming_bench/apps/frappe/frappe/utils/redis_wrapper.py", line 146, in lrange
    return super().lrange(self.make_key(key), start, stop)
  File "/home/office_user/programming_bench/env/lib/python3.10/site-packages/redis/client.py", line 1975, in lrange
    return self.execute_command('LRANGE', name, start, end)
  File "/home/office_user/programming_bench/env/lib/python3.10/site-packages/redis/client.py", line 898, in execute_command
    conn = self.connection or pool.get_connection(command_name, **options)
  File "/home/office_user/programming_bench/env/lib/python3.10/site-packages/redis/connection.py", line 1192, in get_connection
    connection.connect()
  File "/home/office_user/programming_bench/env/lib/python3.10/site-packages/redis/connection.py", line 563, in connect
    raise ConnectionError(self._error_message(e))
redis.exceptions.ConnectionError: Error 111 connecting to localhost:13001. Connection refused.
Traceback (most recent call last):
  File "/home/office_user/programming_bench/env/lib/python3.10/site-packages/redis/connection.py", line 559, in connect
    sock = self._connect()
  File "/home/office_user/programming_bench/env/lib/python3.10/site-packages/redis/connection.py", line 615, in _connect
    raise err
  File "/home/office_user/programming_bench/env/lib/python3.10/site-packages/redis/connection.py", line 603, in _connect
    sock.connect(socket_address)
ConnectionRefusedError: [Errno 111] Connection refused

During handling of the above exception, another exception occurred:

Traceback (most recent call last):
  File "/home/office_user/programming_bench/apps/frappe/frappe/monitor.py", line 118, in flush
    logs = frappe.cache().lrange(MONITOR_REDIS_KEY, 0, -1)
  File "/home/office_user/programming_bench/apps/frappe/frappe/utils/redis_wrapper.py", line 146, in lrange
    return super().lrange(self.make_key(key), start, stop)
  File "/home/office_user/programming_bench/env/lib/python3.10/site-packages/redis/client.py", line 1975, in lrange
    return self.execute_command('LRANGE', name, start, end)
  File "/home/office_user/programming_bench/env/lib/python3.10/site-packages/redis/client.py", line 898, in execute_command
    conn = self.connection or pool.get_connection(command_name, **options)
  File "/home/office_user/programming_bench/env/lib/python3.10/site-packages/redis/connection.py", line 1192, in get_connection
    connection.connect()
  File "/home/office_user/programming_bench/env/lib/python3.10/site-packages/redis/connection.py", line 563, in connect
    raise ConnectionError(self._error_message(e))
redis.exceptions.ConnectionError: Error 111 connecting to localhost:13001. Connection refused.
Traceback (most recent call last):
  File "/home/office_user/programming_bench/env/lib/python3.10/site-packages/redis/connection.py", line 559, in connect
    sock = self._connect()
  File "/home/office_user/programming_bench/env/lib/python3.10/site-packages/redis/connection.py", line 615, in _connect
    raise err
  File "/home/office_user/programming_bench/env/lib/python3.10/site-packages/redis/connection.py", line 603, in _connect
    sock.connect(socket_address)
ConnectionRefusedError: [Errno 111] Connection refused

During handling of the above exception, another exception occurred:

Traceback (most recent call last):
  File "/home/office_user/programming_bench/apps/frappe/frappe/monitor.py", line 118, in flush
    logs = frappe.cache().lrange(MONITOR_REDIS_KEY, 0, -1)
  File "/home/office_user/programming_bench/apps/frappe/frappe/utils/redis_wrapper.py", line 146, in lrange
    return super().lrange(self.make_key(key), start, stop)
  File "/home/office_user/programming_bench/env/lib/python3.10/site-packages/redis/client.py", line 1975, in lrange
    return self.execute_command('LRANGE', name, start, end)
  File "/home/office_user/programming_bench/env/lib/python3.10/site-packages/redis/client.py", line 898, in execute_command
    conn = self.connection or pool.get_connection(command_name, **options)
  File "/home/office_user/programming_bench/env/lib/python3.10/site-packages/redis/connection.py", line 1192, in get_connection
    connection.connect()
  File "/home/office_user/programming_bench/env/lib/python3.10/site-packages/redis/connection.py", line 563, in connect
    raise ConnectionError(self._error_message(e))
redis.exceptions.ConnectionError: Error 111 connecting to localhost:13001. Connection refused.
/home/office_user/programming_bench/env/lib/python3.10/site-packages/botocore/httpsession.py:19: DeprecationWarning: 'urllib3.contrib.pyopenssl' module is deprecated and will be removed in a future release of urllib3 2.x. Read more in this issue: https://github.com/urllib3/urllib3/issues/2680
  from urllib3.contrib.pyopenssl import orig_util_SSLContext as SSLContext
/home/office_user/programming_bench/env/lib/python3.10/site-packages/botocore/httpsession.py:19: DeprecationWarning: 'urllib3.contrib.pyopenssl' module is deprecated and will be removed in a future release of urllib3 2.x. Read more in this issue: https://github.com/urllib3/urllib3/issues/2680
  from urllib3.contrib.pyopenssl import orig_util_SSLContext as SSLContext
fatal: No remote configured to list refs from.
/home/office_user/programming_bench/env/lib/python3.10/site-packages/botocore/httpsession.py:19: DeprecationWarning: 'urllib3.contrib.pyopenssl' module is deprecated and will be removed in a future release of urllib3 2.x. Read more in this issue: https://github.com/urllib3/urllib3/issues/2680
  from urllib3.contrib.pyopenssl import orig_util_SSLContext as SSLContext
/home/office_user/programming_bench/env/lib/python3.10/site-packages/botocore/httpsession.py:19: DeprecationWarning: 'urllib3.contrib.pyopenssl' module is deprecated and will be removed in a future release of urllib3 2.x. Read more in this issue: https://github.com/urllib3/urllib3/issues/2680
  from urllib3.contrib.pyopenssl import orig_util_SSLContext as SSLContext
fatal: No remote configured to list refs from.
Exception in thread Thread-1:
Traceback (most recent call last):
  File "/usr/lib/python3.10/threading.py", line 1016, in _bootstrap_inner
    self.run()
  File "/home/office_user/programming_bench/env/lib/python3.10/site-packages/redis/client.py", line 3718, in run
    pubsub.get_message(ignore_subscribe_messages=True,
  File "/home/office_user/programming_bench/env/lib/python3.10/site-packages/redis/client.py", line 3617, in get_message
    response = self.parse_response(block=False, timeout=timeout)
  File "/home/office_user/programming_bench/env/lib/python3.10/site-packages/redis/client.py", line 3503, in parse_response
    if not block and not conn.can_read(timeout=timeout):
  File "/home/office_user/programming_bench/env/lib/python3.10/site-packages/redis/connection.py", line 734, in can_read
    return self._parser.can_read(timeout)
  File "/home/office_user/programming_bench/env/lib/python3.10/site-packages/redis/connection.py", line 416, in can_read
    return self.read_from_socket(timeout=timeout,
  File "/home/office_user/programming_bench/env/lib/python3.10/site-packages/redis/connection.py", line 429, in read_from_socket
    raise ConnectionError(SERVER_CLOSED_CONNECTION_ERROR)
redis.exceptions.ConnectionError: Connection closed by server.
/home/office_user/programming_bench/env/lib/python3.10/site-packages/botocore/httpsession.py:19: DeprecationWarning: 'urllib3.contrib.pyopenssl' module is deprecated and will be removed in a future release of urllib3 2.x. Read more in this issue: https://github.com/urllib3/urllib3/issues/2680
  from urllib3.contrib.pyopenssl import orig_util_SSLContext as SSLContext
/home/office_user/programming_bench/env/lib/python3.10/site-packages/botocore/httpsession.py:19: DeprecationWarning: 'urllib3.contrib.pyopenssl' module is deprecated and will be removed in a future release of urllib3 2.x. Read more in this issue: https://github.com/urllib3/urllib3/issues/2680
  from urllib3.contrib.pyopenssl import orig_util_SSLContext as SSLContext
fatal: No remote configured to list refs from.
